Workbook
Name AliBEVBattCap: #REF!
Name AliBEVBattCap: #REF!
Name AliBEVBattCap: #REF!
Name AliBEVBattCap: #REF!
Name AliBEVBattCap: #REF!
Name AliBEVBattCap: #REF!
Name AliBEVBattCap: #REF!
Name AliBEVBattCap: #REF!
Name AliBEVBattCap: #REF!
Name AliBEVBattCap: #REF!
Name AliBEVBattCap: #REF!
Name AliBEVBattCap: #REF!
Name AliBEVBattCap: #REF!
Name AliBEVBattCap: #REF!
Name AliBEVBattCap: #REF!
Name AliBEVBattCap: #REF!
Name AliBEVBattCap: #REF!
Name AliBEVBattCap: #REF!
Name AliBEVBattCap: #REF!
Name AliBEVBattCap: #REF!
Name AliBEVBattCap: #REF!
Name AliBEVBattCap: #REF!
Name AliBkWhpYear: #REF!
Name AliBkWhpYear: #REF!
Name AliBkWhpYear: #REF!
Name AliBkWhpYear: #REF!
Name AliBkWhpYear: #REF!
Name AliBkWhpYear: #REF!
Name AliBkWhpYear: #REF!
Name AliBkWhpYear: #REF!
Name AliBkWhpYear: #REF!
Name AliBkWhpYear: #REF!
Name AliBkWhpYear: #REF!
Name AliBkWhpYear: #REF!
Name AliBkWhpYear: #REF!
Name AliBkWhpYear: #REF!
Name AliBkWhpYear: #REF!
Name AliBkWhpYear: #REF!
Name AliBkWhpYear: #REF!
Name AliBkWhpYear: #REF!
Name AliBkWhpYear: #REF!
Name AliBkWhpYear: #REF!
Name AliBkWhpYear: #REF!
Name AliBkWhpYear: #REF!
Name AliBOppChargeFact: #REF!
Name AliBOppChargeFact: #REF!
Name AliBOppChargeFact: #REF!
Name AliBOppChargeFact: #REF!
Name AliBOppChargeFact: #REF!
Name AliBOppChargeFact: #REF!
Name AliBOppChargeFact: #REF!
Name AliBOppChargeFact: #REF!
Name AliBOppChargeFact: #REF!
Name AliBOppChargeFact: #REF!
Name AliBOppChargeFact: #REF!
Name AliBOppChargeFact: #REF!
Name AliBOppChargeFact: #REF!
Name AliBOppChargeFact: #REF!
Name AliBOppChargeFact: #REF!
Name AliBOppChargeFact: #REF!

Sheet Parameters Fixed
D3: 19T Rigid Market L | E3: 28T Rigid Market L | F3: 48T Rigid Market L | G3: 19T Rigid Parcel | H3: 28T Rigid Parcel | I3: 15T Rigid Perishble | J3: 28T Tip C&M | K3: 35T Tip C&M | L3: 48T Rigid Cement | M3: 55T TT Cement | N3: 55T TT Cement | O3: 28T Rigid POL Tnkr | P3: 28T Rigid NonPOL | Q3: 40T TT LPG
A4: 1 | B4: Fuel/Energy Efficienchy (kmpl, km.kg & kWh/km | C4: Diesel | D4: 5.2 | E4: 4.5 | F4: 2.9 | G4: 5 | H4: 4.5 | I4: 6 | J4: 3.8 | K4: 3 | L4: 2.9 | M4: 2.6 | N4: 2.6 | O4: 4.7 | P4: 4.7 | Q4: 3.6
C5: CNG | D5: 5.4 | E5: 4.8 | F5: 3.1 | G5: 5.4 | H5: 4.8 | I5: 6.3 | J5: 4 | K5: 3.2 | L5: 3.1 | M5: 2.8 | N5: 2.7 | O5: 4.9 | P5: 4.9 | Q5: 3.8
C6: LNG | D6: =(D4+D5)/2 -> 5.3 | E6: =(E4+E5)/2 -> 4.65 | F6: =(F4+F5)/2 -> 3 | G6: =(G4+G5)/2 -> 5.2 | H6: =(H4+H5)/2 -> 4.65 | I6: =(I4+I5)/2 -> 6.15 | J6: =(J4+J5)/2 -> 3.9 | K6: =(K4+K5)/2 -> 3.1 | ... Q6: =(Q4+Q5)/2 -> 3.7
C7: H2 ICE | D7: =D4*3 -> 15.6 | E7: =E4*3 -> 13.5 | F7: =F4*3 -> 8.7 | G7: =G4*3 -> 15 | H7: =H4*3 -> 13.5 | I7: =I4*3 -> 18 | J7: =J4*3 -> 11.4 | K7: =K4*3 -> 9 | ... Q7: =Q4*3 -> 10.8
C8: BET | D8: 0.95 | E8: 1.2 | F8: 1.35 | G8: 0.9 | H8: 1.15 | I8: 0.85 | J8: 1.3 | K8: 1.4 | L8: 1.4 | M8: 1.45 | N8: 1.4 | O8: 1.05 | P8: 1.05 | Q8: 1.25
C9: H2 FCET | D9: =D4*4 -> 20.8 | E9: =E4*4 -> 18 | F9: =F4*4 -> 11.6 | G9: =G4*4 -> 20 | H9: =H4*4 -> 18 | I9: =I4*4 -> 24 | J9: =J4*4 -> 15.2 | K9: =K4*4 -> 12 | ... Q9: =Q4*4 -> 14.4
A10: 2 | B10: Weights (kgs.) | C10: GVW | D10: 18500 | E10: 28000 | F10: 47500 | G10: 18500 | H10: 28000 | I10: 16000 | J10: 28000 | K10: 35000 | L10: 47500 | M10: 55000 | N10: 55000 | O10: 28000 | P10: 28000 | Q10: 39500
C11: ULW (ICE Trucks) | D11: 8000 | E11: 9000 | F11: 12500 | G11: 8000 | H11: 9500 | I11: 6500 | J11: 13500 | K11: 15000 | L11: 12500 | M11: 15500 | N11: 15000 | O11: 9500 | P11: 9500 | Q11: 19000
A12: 3 | B12: Maintenance Cost per km (incl. Tyres, suspension/body repairs, Battery & Fuel Cell Replacements (average for 10 years of operation) - Rs./km. in 2025 | C12: Diesel | D12: 2.8 | E12: 4.2 | F12: 7.7 | G12: 2.8 | H12: 4.2 | I12: 3.1 | J12: 8.6 | K12: 10.9 | L12: 7.7 | M12: 6.5 | N12: 8.3 | O12: 3.5 | P12: 3.5 | Q12: 4.3
C13: CNG/LNG/H2 ICE | D13: 3.3 | E13: 4.7 | F13: 8.2 | G13: 3.3 | H13: 4.7 | I13: 3.6 | J13: 9.1 | K13: 11.4 | L13: 8.2 | M13: 7 | N13: 8.8 | O13: 4 | P13: 4 | Q13: 4.8
C14: BET | D14: 3.2223832 | E14: 4.0777952 | F14: 5.071053 | G14: 3.4223832 | H14: 3.822979 | I14: 2.9981448 | J14: 5.1684913 | K14: 5.6727918 | L14: 4.9389099 | M14: 4.5635747 | N14: 4.9840216 | O14: 3.9351253 | P14: 3.9549666 | Q14: 4.6373487
C15: H2 FCET | D15: 3.8648341 | E15: 4.12 | F15: 5.4782857 | G15: 4.0966667 | H15: 3.9366667 | I15: 3.605 | J15: 6.1212 | K15: 6.238 | L15: 5.4421429 | M15: 5.447619 | N15: 5.6785714 | O15: 4.7702 | P15: 4.3702 | Q15: 5.6425
A16: 4 | B16: Maintenance Cost per km (incl. Tyres, suspension/body repairs, Battery & Fuel Cell Replacements (average for 10 years of operation) - Rs./km. in 2055 | C16: Diesel | D16: 9.081513 | E16: 13.62227 | F16: 24.974161 | G16: 9.081513 | H16: 13.62227 | I16: 10.054532 | J16: 27.893219 | K16: 35.353033 | L16: 24.974161 | M16: 21.082084 | N16: 26.920199 | O16: 11.351891 | P16: 11.351891 | Q16: 13.946609
C17: CNG/LNG/H2 ICE | D17: 10.703212 | E17: 15.243968 | F17: 26.59586 | G17: 10.703212 | H17: 15.243968 | I17: 11.676231 | J17: 29.514917 | K17: 36.974732 | L17: 26.59586 | M17: 22.703783 | N17: 28.541898 | O17: 12.97359 | P17: 12.97359 | Q17: 15.568308
C18: BET | D18: 8.828151 | E18: 13.407945 | F18: 24.893202 | G18: 8.9650097 | H18: 13.233576 | I18: 9.6477253 | J18: 21.596309 | K18: 28.854898 | L18: 24.802777 | M18: 21.473333 | N18: 27.599158 | O18: 11.313097 | P18: 11.326674 | Q18: 14.661499
C19: H2 FCET | D19: 9.2677762 | E19: 13.436826 | F19: 25.171868 | G19: 9.4264178 | H19: 13.311372 | I19: 10.062993 | J19: 22.248242 | K19: 29.241666 | L19: 25.147136 | M19: 22.078279 | N19: 28.074434 | O19: 11.884533 | P19: 11.610816 | Q19: 15.349318
A20: 5 | B20: Adblue Consumption/ litre of Diesel Consumed | D20: 0.05
A21: 6 | B21: Battery Life (full charging cycles) | D21: 3000
B22: Fuel Cell Life (hrs. of operation) | D22: 25000
A23: 7 | B23: Battery Energy Density (kg./kWh) | D23: 8 | E23: Used for calculation of Payload reduction
B24: Fuel Cell Power Density (kg./kW) | D24: 4
A25: 8 | B25: Funding | C25: Interest Rate | D25: 0.12
C26: Tenure (years) | D26: 7
A27: 9 | B27: Insurance Rate (% of Vehicle Price) | D27: 0.02
A28: 10 | B28: CNG Cylinders in Vehicle | C28: Capacity (ltrs.) | D28: 480 | E28: 960
C29: CNG Density (kg./ltr.) | D29: 0.2
C30: Capacity (kgs.) | D30: =D28*D29 -> 96 | E30: =E28*D29 -> 192
C31: Cost (Rs.) | D31: 150000 | E31: 250000
A32: 11 | B32: LNG Cylinders in Vehicle | C32: Capacity (ltrs.) | D32: 450 | E32: 990
C33: LNG Density (kg./ltr.) | D33: 0.35
C34: Capacity (kgs.) | D34: =D32*D33 -> 157.5 | E34: =E32*D33 -> 346.5
A35: 12 | B35: H2 Cylinders in Vehicle (350 bar pressure) | C35: Capacity (ltrs.) | D35: 1200 | E35: 2400
C36: H2 Density (kg./cu.M) | D36: 23.5
C37: Capacity (kgs.) | D37: =D35*D36/1000 -> 28.2 | E37: =E35*D36/1000 -> 56.4
D38: Diesel | E38: CNG | F38: LNG | G38: BET | H38: H2 ICE | I38: H2 FCET
A39: 13 | B39: TAT / gradeability / Productivity | C39: Relative Weightage | D39: 1 | E39: 0.95 | F39: 0.95 | G39: 1.15 | H39: 0.95 | I39: 1.15
A40: 14 | B40: Range & filling time | D40: 1 | E40: 1.05 | F40: 1.1 | G40: 1.2 | H40: 1 | I40: 1
A41: 15 | B41: Product & Eco-system Readiness (Year) | C41: Model | D41: Product Pilot | J41: Start of Supply (All Geography) | P41: Maturity (Products & Eco-system) | V41: Inflection Point (10% share)
D42: Diesel | E42: CNG | F42: LNG | G42: BET | H42: H2 ICE | I42: H2 FCET | J42: Diesel | K42: CNG | L42: LNG | M42: BET | N42: H2 ICE | O42: H2 FCET | P42: Diesel | Q42: CNG | R42: LNG | S42: BET | T42: H2 ICE | U42: H2 FCET | V42: BET | W42: H2 ICE | X42: H2 FCET
...

Sheet Parameters Varying
A2: Sl. No. | B2: Parameter | D2: Base Value 2025 | E2: Value 2055 | F2: Trend | L2: CAGR | M2: Remarks
F3: 2026-30 | G3: 2031-35 | H3: 2036-40 | I3: 2041-45 | J3: 2046-56 | K3: 2050-55
A4: 1 | B4: Diesel Price per litre | D4: ='Changing with year'!C3 -> 88.926296 | E4: ='Changing with year'!AG3 -> 175.80862 | F4: (Annual values as per WRI Estimates) | L4: =_xlfn.RRI(30,D4,E4) -> 0.022979661
A5: 2 | B5: Adblue Price | D5: ='Changing with year'!C4 -> 55 | E5: ='Changing with year'!AG4 -> 115.36622 | F5: ='Changing with year'!AH4 -> 0.025 | G5: ='Changing with year'!AI4 -> 0.025 | H5: ='Changing with year'!AI4 -> 0.025 | I5: ='Changing with year'!AJ4 -> 0.025 | J5: ='Changing with year'!AJ4 -> 0.025 | K5: ='Changing with year'!AK4 -> 0.025
A6: 3 | B6: CNG Price per kg | D6: ='Changing with year'!C5 -> 87 | E6: ='Changing with year'!AG5 -> 215.62574 | F6: ='Changing with year'!AH5 -> 0.03 | G6: ='Changing with year'!AI5 -> 0.03 | H6: ='Changing with year'!AI5 -> 0.03 | I6: ='Changing with year'!AJ5 -> 0.03 | J6: ='Changing with year'!AJ5 -> 0.03 | K6: ='Changing with year'!AK5 -> 0.03
A7: 4 | B7: LNG Price per kg | D7: ='Changing with year'!C6 -> 83 | E7: ='Changing with year'!AG6 -> 202.66463 | F7: ='Changing with year'!AH6 -> 0.03 | G7: ='Changing with year'!AI6 -> 0.03 | H7: ='Changing with year'!AI6 -> 0.03 | I7: ='Changing with year'!AJ6 -> 0.03 | J7: ='Changing with year'!AJ6 -> 0.03 | K7: ='Changing with year'!AK6 -> 0.03
A8: 5 | B8: Electricity incl CAAS (Rs./kWh) | C8: Electricity incl DC | D8: ='Changing with year'!#REF! -> #REF! | E8: ='Changing with year'!#REF! -> #REF! | F8: ='Changing with year'!#REF! -> #REF! | G8: ='Changing with year'!#REF! -> #REF! | H8: ='Changing with year'!#REF! -> #REF! | I8: ='Changing with year'!#REF! -> #REF! | J8: ='Changing with year'!#REF! -> #REF! | K8: ='Changing with year'!#REF! -> #REF! | L8: =_xlfn.RRI(30,D8,E8) -> #REF!
C9: Real Estate | D9: ='Changing with year'!#REF! -> #REF! | E9: ='Changing with year'!#REF! -> #REF! | F9: ='Changing with year'!#REF! -> #REF! | G9: ='Changing with year'!#REF! -> #REF! | H9: ='Changing with year'!#REF! -> #REF! | I9: ='Changing with year'!#REF! -> #REF! | J9: ='Changing with year'!#REF! -> #REF! | K9: ='Changing with year'!#REF! -> #REF! | L9: =_xlfn.RRI(30,D9,E9) -> #REF!
C10: Charging Infra | D10: ='Changing with year'!#REF! -> #REF! | E10: ='Changing with year'!#REF! -> #REF! | F10: ='Changing with year'!#REF! -> #REF! | G10: ='Changing with year'!#REF! -> #REF! | H10: ='Changing with year'!#REF! -> #REF! | I10: ='Changing with year'!#REF! -> #REF! | J10: ='Changing with year'!#REF! -> #REF! | K10: ='Changing with year'!#REF! -> #REF! | L10: =_xlfn.RRI(30,D10,E10) -> #REF!
C11: Total | D11: ='Changing with year'!C18 -> 11.929848 | E11: ='Changing with year'!AG18 -> 10.603822 | L11: =_xlfn.RRI(30,D11,E11) -> -0.0039199295
A12: 6 | B12: Green H2 Prodn cost/kg | C12: Energy Cost | D12: ='Changing with year'!#REF! -> #REF! | E12: ='Changing with year'!#REF! -> #REF! | F12: ='Changing with year'!#REF! -> #REF! | G12: ='Changing with year'!#REF! -> #REF! | H12: ='Changing with year'!#REF! -> #REF! | I12: ='Changing with year'!#REF! -> #REF! | J12: ='Changing with year'!#REF! -> #REF! | K12: ='Changing with year'!#REF! -> #REF! | L12: =_xlfn.RRI(30,D12,E12) -> #REF!
C13: Capex (USD1.25) | D13: ='Changing with year'!C9 -> 115 | E13: ='Changing with year'!AG9 -> 30.417458 | F13: ='Changing with year'!AH9 -> -0.03 | G13: ='Changing with year'!AI9 -> -0.04 | H13: ='Changing with year'!AI9 -> -0.04 | I13: ='Changing with year'!AJ9 -> -0.05 | J13: ='Changing with year'!AJ9 -> -0.05 | K13: ='Changing with year'!AK9 -> -0.05 | L13: =_xlfn.RRI(30,D13,E13) -> -0.043362276
C14: Opex & Margin | D14: ='Changing with year'!C10 -> 140 | E14: ='Changing with year'!AG10 -> 33.348541 | F14: ='Changing with year'!AH10 -> -0.03 | G14: ='Changing with year'!AI10 -> -0.05 | H14: ='Changing with year'!AI10 -> -0.05 | I14: ='Changing with year'!AJ10 -> -0.05 | J14: ='Changing with year'!AJ10 -> -0.05 | K14: ='Changing with year'!AK10 -> -0.05 | L14: =_xlfn.RRI(30,D14,E14) -> -0.046695536
C15: Total | D15: ='Changing with year'!C11 -> 546.5 | E15: ='Changing with year'!AG11 -> 270.53188 | F15: ='Changing with year'!AH11 -> 0 | G15: ='Changing with year'!AI11 -> 0 | H15: ='Changing with year'!AI11 -> 0 | I15: ='Changing with year'!AJ11 -> 0 | J15: ='Changing with year'!AJ11 -> 0 | K15: ='Changing with year'!AK11 -> 0 | L15: =_xlfn.RRI(30,D15,E15) -> -0.023165606
A16: 7 | B16: Grey H2 Prodn Cost/kg | D16: ='Changing with year'!C12 -> 250 | E16: ='Changing with year'!AG12 -> 452.8404 | F16: ='Changing with year'!AH12 -> 0.02 | G16: ='Changing with year'!AI12 -> 0.02 | H16: ='Changing with year'!AI12 -> 0.02 | I16: ='Changing with year'!AJ12 -> 0.02 | J16: ='Changing with year'!AJ12 -> 0.02 | K16: ='Changing with year'!AK12 -> 0.02
A17: 8 | B17: H2 Compression, storage & transmission cost/kg | D17: ='Changing with year'!C14 -> 175 | E17: ='Changing with year'!AG14 -> 70.138953 | F17: ='Changing with year'!AH14 -> -0.04 | G17: ='Changing with year'!AI14 -> -0.03 | H17: ='Changing with year'!AI14 -> -0.03 | I17: ='Changing with year'!AJ14 -> -0.03 | J17: ='Changing with year'!AJ14 -> -0.03 | K17: ='Changing with year'!AK14 -> -0.02 | L17: =_xlfn.RRI(30,D17,E17) -> -0.030017183
A18: 9 | B18: Battery cost per kwh | D18: ='Changing with year'!C19 -> 9900 | E18: ='Changing with year'!AG19 -> 6773.6276 | F18: ='Changing with year'!AH19 -> -0.015 | G18: ='Changing with year'!AI19 -> -0.025 | H18: ='Changing with year'!AI19 -> -0.025 | I18: ='Changing with year'!AJ19 -> -0.01 | J18: ='Changing with year'!AJ19 -> -0.01 | K18: ='Changing with year'!AK19 -> 0.01 | L18: =_xlfn.RRI(30,D18,E18) -> -0.012570258
A19: 10 | B19: Fuel Cell cost per kW | D19: ='Changing with year'!C20 -> 36000 | E19: ='Changing with year'!AG20 -> 19577 | F19: ='Changing with year'!AH20 -> -0.03 | G19: ='Changing with year'!AI20 -> -0.03 | H19: ='Changing with year'!AI20 -> -0.03 | I19: ='Changing with year'!AJ20 -> -0.02 | J19: ='Changing with year'!AJ20 -> -0.02 | K19: ='Changing with year'!AK20 -> 0.01 | L19: =_xlfn.RRI(30,D19,E19) -> -0.020100684
A20: 11 | B20: LNG Tank cost/kg of LNG | D20: ='Changing with year'!C21 -> 3050 | E20: ='Changing with year'!AG21 -> 4110.9392 | F20: ='Changing with year'!AH21 -> 0.01 | G20: ='Changing with year'!AI21 -> 0.01 | H20: ='Changing with year'!AI21 -> 0.01 | I20: ='Changing with year'!AJ21 -> 0.01 | J20: ='Changing with year'!AJ21 -> 0.01 | K20: ='Changing with year'!AK21 -> 0.01
A21: 12 | B21: LNG Valves & Piping cost/vehicle | D21: ='Changing with year'!C22 -> 100000 | E21: ='Changing with year'!AG22 -> 134784.89 | F21: ='Changing with year'!AH22 -> 0.01 | G21: ='Changing with year'!AI22 -> 0.01 | H21: ='Changing with year'!AI22 -> 0.01 | I21: ='Changing with year'!AJ22 -> 0.01 | J21: ='Changing with year'!AJ22 -> 0.01 | K21: ='Changing with year'!AK22 -> 0.01
A22: 13 | B22: H2 Tank cost/kg of H2 | D22: ='Changing with year'!C23 -> 56000 | E22: ='Changing with year'!AG23 -> 33445.6 | F22: ='Changing with year'!AH23 -> -0.05 | G22: ='Changing with year'!AI23 -> -0.04 | H22: ='Changing with year'!AI23 -> -0.04 | I22: ='Changing with year'!AJ23 -> 0.01 | J22: ='Changing with year'!AJ23 -> 0.01 | K22: ='Changing with year'!AK23 -> 0.01 | L22: =_xlfn.RRI(30,D22,E22) -> -0.017034296
A23: 14 | B23: Cost of Engine & Transmission (Diesel) | C23: 15T Rigid | D23: ='Changing with year'!C26 -> 525000 | E23: ='Changing with year'!AG26 -> 950964.83 | F23: ='Changing with year'!AH26 -> 0.02 | G23: ='Changing with year'!AI26 -> 0.02 | H23: ='Changing with year'!AI26 -> 0.02 | I23: ='Changing with year'!AJ26 -> 0.02 | J23: ='Changing with year'!AJ26 -> 0.02 | K23: ='Changing with year'!AK26 -> 0.02 | M23: Other Model costs in hidden rows
C24: 19T Rigid | D24: ='Changing with year'!C27 -> 625000 | E24: ='Changing with year'!AG27 -> 1132101 | F24: ='Changing with year'!AH27 -> 0.02 | G24: ='Changing with year'!AI27 -> 0.02 | H24: ='Changing with year'!AI27 -> 0.02 | I24: ='Changing with year'!AJ27 -> 0.02 | J24: ='Changing with year'!AJ27 -> 0.02 | K24: ='Changing with year'!AK27 -> 0.02
C25: 28T/35T Rigid | D25: ='Changing with year'!C28 -> 650000 | E25: ='Changing with year'!AG28 -> 1177385 | F25: ='Changing with year'!AH28 -> 0.02 | G25: ='Changing with year'!AI28 -> 0.02 | H25: ='Changing with year'!AI28 -> 0.02 | I25: ='Changing with year'!AJ28 -> 0.02 | J25: ='Changing with year'!AJ28 -> 0.02 | K25: ='Changing with year'!AK28 -> 0.02
C26: 48T Rigid | D26: ='Changing with year'!C30 -> 750000 | E26: ='Changing with year'!AG30 -> 1358521.2 | F26: ='Changing with year'!AH30 -> 0.02 | G26: ='Changing with year'!AI30 -> 0.02 | H26: ='Changing with year'!AI30 -> 0.02 | I26: ='Changing with year'!AJ30 -> 0.02 | J26: ='Changing with year'!AJ30 -> 0.02 | K26: ='Changing with year'!AK30 -> 0.02
C27: 28T Tipper | D27: ='Changing with year'!C31 -> 650000 | E27: ='Changing with year'!AG31 -> 1177385 | F27: ='Changing with year'!AH31 -> 0.02 | G27: ='Changing with year'!AI31 -> 0.02 | H27: ='Changing with year'!AI31 -> 0.02 | I27: ='Changing with year'!AJ31 -> 0.02 | J27: ='Changing with year'!AJ31 -> 0.02 | K27: ='Changing with year'!AK31 -> 0.02
C28: 35T Tipper | D28: ='Changing with year'!C32 -> 750000 | E28: ='Changing with year'!AG32 -> 1358521.2 | F28: ='Changing with year'!AH32 -> 0.02 | G28: ='Changing with year'!AI32 -> 0.02 | H28: ='Changing with year'!AI32 -> 0.02 | I28: ='Changing with year'!AJ32 -> 0.02 | J28: ='Changing with year'!AJ32 -> 0.02 | K28: ='Changing with year'!AK32 -> 0.02
C29: 40T Tractor | D29: ='Changing with year'!C33 -> 650000 | E29: ='Changing with year'!AG33 -> 1177385 | F29: ='Changing with year'!AH33 -> 0.02 | G29: ='Changing with year'!AI33 -> 0.02 | H29: ='Changing with year'!AI33 -> 0.02 | I29: ='Changing with year'!AJ33 -> 0.02 | J29: ='Changing with year'!AJ33 -> 0.02 | K29: ='Changing with year'!AK33 -> 0.02
C30: 55T Tractor | D30: ='Changing with year'!C34 -> 750000 | E30: ='Changing with year'!AG34 -> 1358521.2 | F30: ='Changing with year'!AH34 -> 0.02 | G30: ='Changing with year'!AI34 -> 0.02 | H30: ='Changing with year'!AI34 -> 0.02 | I30: ='Changing with year'!AJ34 -> 0.02 | J30: ='Changing with year'!AJ34 -> 0.02 | K30: ='Changing with year'!AK34 -> 0.02
A31: 15 | B31: Cost of e-Powertrain | C31: 15T/19T/28T Rigid & 40T TT | D31: ='Changing with year'!C37 -> 1400000 | E31: ='Changing with year'!AG37 -> 1198551.6 | F31: ='Changing with year'!AH37 -> -0.04 | G31: ='Changing with year'!AI37 -> -0.01 | H31: ='Changing with year'!AI37 -> -0.01 | I31: ='Changing with year'!AJ37 -> 0.01 | J31: ='Changing with year'!AJ37 -> 0.01 | K31: ='[1]Changing with year'!AK30 -> 0.01 | L31: =_xlfn.RRI(30,D31,E31) -> -0.0051652264
C32: 35T/48T Rigid, 28T/35T Tip & 55T TT | D32: ='Changing with year'!C40 -> 1700000 | E32: ='Changing with year'!AG40 -> 1455384.1 | F32: ='Changing with year'!AH40 -> -0.04 | G32: ='Changing with year'!AI40 -> -0.01 | H32: ='Changing with year'!AI40 -> -0.01 | I32: ='Changing with year'!AJ40 -> 0.01 | J32: ='Changing with year'!AJ40 -> 0.01 | K32: ='[1]Changing with year'!AK33 -> 0.01 | L32: =_xlfn.RRI(30,D32,E32) -> -0.0051652264
A33: 16 | B33: Diesel Vehicle Cost (Acquistion Cost incl. body/trailer, permit, registration, etc.) | C33: 15T Rigid | D33: ='Changing with year'!C81 -> 2000000 | E33: ='Changing with year'!AG81 -> 5692200 | F33: ='Changing with year'!AH81 -> 0.03 | G33: ='Changing with year'!AI81 -> 0.03 | H33: ='Changing with year'!AI81 -> 0.03 | I33: ='Changing with year'!AJ81 -> 0.03 | J33: ='Changing with year'!AJ81 -> 0.03 | K33: ='Changing with year'!AK81 -> 0.03 | M33: Other Model costs in hidden rows
C34: 19T Rigid | D34: ='Changing with year'!C82 -> 2750000 | E34: ='Changing with year'!AG82 -> 7513000 | F34: ='Changing with year'!AH82 -> 0.03 | G34: ='Changing with year'!AI82 -> 0.03 | H34: ='Changing with year'!AI82 -> 0.03 | I34: ='Changing with year'!AJ82 -> 0.03 | J34: ='Changing with year'!AJ82 -> 0.03 | K34: ='Changing with year'!AK82 -> 0.03
C35: 28T Rigid | D35: ='Changing with year'!C83 -> 3600000 | E35: ='Changing with year'!AG83 -> 9575700 | F35: ='Changing with year'!AH83 -> 0.03 | G35: ='Changing with year'!AI83 -> 0.03 | H35: ='Changing with year'!AI83 -> 0.03 | I35: ='Changing with year'!AJ83 -> 0.03 | J35: ='Changing with year'!AJ83 -> 0.03 | K35: ='Changing with year'!AK83 -> 0.03
C36: 35T Rigid | D36: ='Changing with year'!C84 -> 4000000 | E36: ='Changing with year'!AG84 -> 10546400 | F36: ='Changing with year'!AH84 -> 0.03 | G36: ='Changing with year'!AI84 -> 0.03 | H36: ='Changing with year'!AI84 -> 0.03 | I36: ='Changing with year'!AJ84 -> 0.03 | J36: ='Changing with year'!AJ84 -> 0.03 | K36: ='Changing with year'!AK84 -> 0.03
C37: 48T Rigid | D37: ='Changing with year'!C85 -> 4700000 | E37: ='Changing with year'!AG85 -> 12245900 | F37: ='Changing with year'!AH85 -> 0.03 | G37: ='Changing with year'!AI85 -> 0.03 | H37: ='Changing with year'!AI85 -> 0.03 | I37: ='Changing with year'!AJ85 -> 0.03 | J37: ='Changing with year'!AJ85 -> 0.03 | K37: ='Changing with year'!AK85 -> 0.03
C38: 28T Tipper | D38: ='Changing with year'!C86 -> 4200000 | E38: ='Changing with year'!AG86 -> 11032100 | F38: ='Changing with year'!AH86 -> 0.03 | G38: ='Changing with year'!AI86 -> 0.03 | H38: ='Changing with year'!AI86 -> 0.03 | I38: ='Changing with year'!AJ86 -> 0.03 | J38: ='Changing with year'!AJ86 -> 0.03 | K38: ='Changing with year'!AK86 -> 0.03
C39: 35T Tipper | D39: ='Changing with year'!C87 -> 4800000 | E39: ='Changing with year'!AG87 -> 12488800 | F39: ='Changing with year'!AH87 -> 0.03 | G39: ='Changing with year'!AI87 -> 0.03 | H39: ='Changing with year'!AI87 -> 0.03 | I39: ='Changing with year'!AJ87 -> 0.03 | J39: ='Changing with year'!AJ87 -> 0.03 | K39: ='Changing with year'!AK87 -> 0.03
C40: 40T Tractor | D40: ='Changing with year'!C88 -> 4300000 | E40: ='Changing with year'!AG88 -> 11274800 | F40: ='Changing with year'!AH88 -> 0.03 | G40: ='Changing with year'!AI88 -> 0.03 | H40: ='Changing with year'!AI88 -> 0.03 | I40: ='Changing with year'!AJ88 -> 0.03 | J40: ='Changing with year'!AJ88 -> 0.03 | K40: ='Changing with year'!AK88 -> 0.03
C41: 55T Tractor | D41: ='Changing with year'!C89 -> 5000000 | E41: ='Changing with year'!AG89 -> 12973700 | F41: ='Changing with year'!AH89 -> 0.03 | G41: ='Changing with year'!AI89 -> 0.03 | H41: ='Changing with year'!AI89 -> 0.03 | I41: ='Changing with year'!AJ89 -> 0.03 | J41: ='Changing with year'!AJ89 -> 0.03 | K41: ='Changing with year'!AK89 -> 0.03
...

Sheet TCO Compaison
A1: TCO Comparison (Rs./km) - Summary
A2: Sl. No. | B2: Parameter | C2: Powertrain | D2: H2 Cost in 2055 - 330/100 | J2: H2 Cost in 2055 - 220/70 | P2: H2 Cost in 2055 - 170/70 | V2: H2 Cost in line with new Electricity Cost | AB2: TCO
D3: H2 Cost in 2055 - 330/100 | J3: H2 Cost in 2055 - 220/70 | P3: H2 Cost in 2055 - 170/70 | V3: H2 Cost in line with new Electricity Cost | AB3: 2025 | AD3: 2055
D4: TCO 2025 | E4: Diff with Diesel | F4: TCO 2055 | G4: Diff with Diesel | H4: Diff with BET | J4: TCO 2025 | K4: Diff with Diesel | L4: TCO 2055 | M4: Diff with Diesel | N4: Diff with BET | P4: TCO 2025 | Q4: Diff with Diesel | R4: TCO 2055 | S4: Diff with Diesel | T4: Diff with BET | V4: TCO 2025 | W4: Diff with Diesel | X4: TCO 2055 | Y4: Diff with Diesel | Z4: Diff with BET | AB4: TCO 2025 | AC4: Diff with Diesel | AD4: TCO 2055 | AE4: Diff with Diesel | AF4: Diff with BET (Rs.) | AG4: Diff with BET (%) | AK4: Remarks
A6: B1 | B6: 19T Market Load (H2 Cost in 2055 - 220/70) | C6: Diesel | D6: ='B1 - TCO ML 19T'!C165 -> 33.521745 | E6: =D6-D$6 -> 0 | F6: ='B1 - TCO ML 19T'!AG165 -> 78.262657 | G6: =F6-F$6 -> 0 | J6: 33.521745 | K6: =J6-J$6 -> 0 | L6: 75.454311 | M6: =L6-L$6 -> 0 | P6: 33.521745 | Q6: =P6-P$6 -> 0 | R6: 75.454311 | S6: =R6-R$6 -> 0 | V6: 33.521745 | W6: =V6-V$6 -> 0 | X6: 75.454311 | Y6: =X6-X$6 -> 0 | AB6: ='B1 - TCO ML 19T'!C165 -> 33.521745 | AC6: =AB6-AB$6 -> 0 | AD6: ='B1 - TCO ML 19T'!AG165 -> 78.262657 | AE6: =AD6-AD$6 -> 0
C7: CNG | D7: ='B1 - TCO ML 19T'!C166 -> 33.072847 | E7: =D7-D$6 -> -0.44889816 | F7: ='B1 - TCO ML 19T'!AG166 -> 86.495082 | G7: =F7-F$6 -> 8.2324248 | J7: 33.072847 | K7: =J7-J$6 -> -0.44889816 | L7: 80.358533 | M7: =L7-L$6 -> 4.9042215 | P7: 33.072847 | Q7: =P7-P$6 -> -0.44889816 | R7: 80.358533 | S7: =R7-R$6 -> 4.9042215 | V7: 33.072847 | W7: =V7-V$6 -> -0.44889816 | X7: 80.358533 | Y7: =X7-X$6 -> 4.9042215 | AB7: ='B1 - TCO ML 19T'!C166 -> 33.072847 | AC7: =AB7-AB$6 -> -0.44889816 | AD7: ='B1 - TCO ML 19T'!AG166 -> 86.495082 | AE7: =AD7-AD$6 -> 8.2324248
C8: LNG | D8: ='B1 - TCO ML 19T'!C167 -> 33.134497 | E8: =D8-D$6 -> -0.38724836 | F8: ='B1 - TCO ML 19T'!AG167 -> 85.122288 | G8: =F8-F$6 -> 6.8596311 | J8: 33.134497 | K8: =J8-J$6 -> -0.38724836 | L8: 79.732378 | M8: =L8-L$6 -> 4.2780664 | P8: 33.134497 | Q8: =P8-P$6 -> -0.38724836 | R8: 79.732378 | S8: =R8-R$6 -> 4.2780664 | V8: 33.134497 | W8: =V8-V$6 -> -0.38724836 | X8: 79.732378 | Y8: =X8-X$6 -> 4.2780664 | AB8: ='B1 - TCO ML 19T'!C167 -> 33.134497 | AC8: =AB8-AB$6 -> -0.38724836 | AD8: ='B1 - TCO ML 19T'!AG167 -> 85.122288 | AE8: =AD8-AD$6 -> 6.8596311
C9: BET | D9: ='B1 - TCO ML 19T'!C168 -> 40.041671 | E9: =D9-D$6 -> 6.5199255 | F9: ='B1 - TCO ML 19T'!AG168 -> 57.817388 | G9: =F9-F$6 -> -20.445269 | H9: =F9-F$9 -> 0 | J9: 45.808315 | K9: =J9-J$6 -> 12.28657 | L9: 58.600351 | M9: =L9-L$6 -> -16.85396 | N9: =L9-L$9 -> 0 | P9: 45.808315 | Q9: =P9-P$6 -> 12.28657 | R9: 58.600351 | S9: =R9-R$6 -> -16.85396 | T9: =R9-R$9 -> 0 | V9: 45.808315 | W9: =V9-V$6 -> 12.28657 | X9: 62.228801 | Y9: =X9-X$6 -> -13.22551 | Z9: =X9-X$9 -> 0 | AB9: ='B1 - TCO ML 19T'!C168 -> 40.041671 | AC9: =AB9-AB$6 -> 6.5199255 | AD9: ='B1 - TCO ML 19T'!AG168 -> 57.817388 | AE9: =AD9-AD$6 -> -20.445269
C10: H2-ICE | D10: ='B1 - TCO ML 19T'!C169 -> 66.706792 | E10: =D10-D$6 -> 33.185047 | F10: ='B1 - TCO ML 19T'!AG169 -> 67.895607 | G10: =F10-F$6 -> -10.36705 | H10: =F10-F$9 -> 10.078219 | J10: 70.136279 | K10: =J10-J$6 -> 36.614534 | L10: 64.460772 | M10: =L10-L$6 -> -10.993539 | N10: =L10-L$9 -> 5.8604212 | P10: 70.136279 | Q10: =P10-P$6 -> 36.614534 | R10: 61.267884 | S10: =R10-R$6 -> -14.186427 | T10: =R10-R$9 -> 2.667533 | V10: 70.136279 | W10: =V10-V$6 -> 36.614534 | X10: 68.207775 | Y10: =X10-X$6 -> -7.2465361 | Z10: =X10-X$9 -> 5.9789741 | AB10: ='B1 - TCO ML 19T'!C169 -> 66.706792 | AC10: =AB10-AB$6 -> 33.185047 | AD10: ='B1 - TCO ML 19T'!AG169 -> 67.895607 | AE10: =AD10-AD$6 -> -10.36705 | AF10: =AD10-AD$9 -> 10.078219 | AG10: =AF10/AD9 -> 0.17431122
C11: FCET | D11: ='B1 - TCO ML 19T'!C170 -> 72.215837 | E11: =D11-D$6 -> 38.694092 | F11: ='B1 - TCO ML 19T'!AG170 -> 69.073503 | G11: =F11-F$6 -> -9.1891534 | H11: =F11-F$9 -> 11.256116 | J11: 74.787953 | K11: =J11-J$6 -> 41.266207 | L11: 66.497377 | M11: =L11-L$6 -> -8.9569339 | N11: =L11-L$9 -> 7.8970265 | P11: 74.787953 | Q11: =P11-P$6 -> 41.266207 | R11: 64.102711 | S11: =R11-R$6 -> -11.3516 | T11: =R11-R$9 -> 5.5023603 | V11: 74.787953 | W11: =V11-V$6 -> 41.266207 | X11: 69.30763 | Y11: =X11-X$6 -> -6.1466816 | Z11: =X11-X$9 -> 7.0788286 | AB11: ='B1 - TCO ML 19T'!C170 -> 72.215837 | AC11: =AB11-AB$6 -> 38.694092 | AD11: ='B1 - TCO ML 19T'!AG170 -> 69.073503 | AE11: =AD11-AD$6 -> -9.1891534 | AF11: =AD11-AD$9 -> 11.256116 | AG11: =AF11/AD9 -> 0.19468392
C12: Diesel - 10% | D12: ='B1 - TCO ML 19T'!C171 -> 30.169571 | F12: ='B1 - TCO ML 19T'!AG171 -> 70.436391 | J12: 30.169571 | L12: 67.90888 | P12: 30.169571 | R12: 67.90888 | V12: 30.169571 | X12: 67.90888 | AB12: ='B1 - TCO ML 19T'!C171 -> 30.169571 | AD12: ='B1 - TCO ML 19T'!AG171 -> 70.436391
A14: B3 | B14: 48T Market Load (H2 Cost in 2055 - 220/70) | C14: Diesel | D14: 61.165655 | E14: =D14-D$14 -> 0 | F14: 137.75029 | G14: =F14-F$14 -> 0 | J14: 61.165655 | L14: 137.75029 | P14: 61.165655 | R14: 137.75029 | V14: 61.165655 | X14: 137.75029 | AB14: ='B3 - TCO ML 48T '!C165 -> 61.165655 | AD14: ='B3 - TCO ML 48T '!AG165 -> 142.78594
C15: CNG | D15: 58.833206 | E15: =D15-D$14 -> -2.3324495 | F15: 142.61354 | G15: =F15-F$14 -> 4.8632576 | J15: 58.833206 | K15: =J15-J$14 -> -2.3324495 | L15: 142.61354 | M15: =L15-L$14 -> 4.8632576 | P15: 58.833206 | Q15: =P15-P$14 -> -2.3324495 | R15: 142.61354 | S15: =R15-R$14 -> 4.8632576 | V15: 58.833206 | W15: =V15-V$14 -> -2.3324495 | X15: 142.61354 | Y15: =X15-X$14 -> 4.8632576 | AB15: ='B3 - TCO ML 48T '!C166 -> 58.833206 | AC15: =AB15-AB$14 -> -2.3324495 | AD15: ='B3 - TCO ML 48T '!AG166 -> 153.30302 | AE15: =AD15-AD$14 -> 10.517076
C16: LNG | D16: 58.969566 | E16: =D16-D$14 -> -2.19609 | F16: 142.1105 | G16: =F16-F$14 -> 4.3602137 | J16: 58.969566 | K16: =J16-J$14 -> -2.19609 | L16: 142.1105 | M16: =L16-L$14 -> 4.3602137 | P16: 58.969566 | Q16: =P16-P$14 -> -2.19609 | R16: 142.1105 | S16: =R16-R$14 -> 4.3602137 | V16: 58.969566 | W16: =V16-V$14 -> -2.19609 | X16: 142.1105 | Y16: =X16-X$14 -> 4.3602137 | AB16: ='B3 - TCO ML 48T '!C167 -> 58.969566 | AC16: =AB16-AB$14 -> -2.19609 | AD16: ='B3 - TCO ML 48T '!AG167 -> 151.63268 | AE16: =AD16-AD$14 -> 8.8467343
C17: BET | D17: 74.461126 | E17: =D17-D$14 -> 13.29547 | F17: 102.3916 | G17: =F17-F$14 -> -35.358684 | H17: =F17-F$17 -> 0 | J17: 74.461126 | K17: =J17-J$14 -> 13.29547 | L17: 102.3916 | M17: =L17-L$14 -> -35.358684 | N17: =L17-L$17 -> 0 | P17: 74.461126 | Q17: =P17-P$14 -> 13.29547 | R17: 102.3916 | S17: =R17-R$14 -> -35.358684 | T17: =R17-R$17 -> 0 | V17: 74.461126 | W17: =V17-V$14 -> 13.29547 | X17: 107.54782 | Y17: =X17-X$14 -> -30.202466 | Z17: =X17-X$17 -> 0 | AB17: ='B3 - TCO ML 48T '!C168 -> 66.26642 | AC17: =AB17-AB$14 -> 5.1007647 | AD17: ='B3 - TCO ML 48T '!AG168 -> 101.27897 | AE17: =AD17-AD$14 -> -41.50697
C18: H2-ICE | D18: 124.07694 | E18: =D18-D$14 -> 62.911288 | F18: 131.67055 | G18: =F18-F$14 -> -6.0797333 | H18: =F18-F$17 -> 29.278951 | J18: 124.07694 | K18: =J18-J$14 -> 62.911288 | L18: 115.635 | M18: =L18-L$14 -> -22.115291 | N18: =L18-L$17 -> 13.243393 | P18: 124.07694 | Q18: =P18-P$14 -> 62.911288 | R18: 109.90982 | S18: =R18-R$14 -> -27.84047 | T18: =R18-R$17 -> 7.518214 | V18: 124.07694 | W18: =V18-V$14 -> 62.911288 | X18: 122.35376 | Y18: =X18-X$14 -> -15.396527 | Z18: =X18-X$17 -> 14.805938 | AB18: ='B3 - TCO ML 48T '!C169 -> 117.92752 | AC18: =AB18-AB$14 -> 56.761863 | AD18: ='B3 - TCO ML 48T '!AG169 -> 121.79401 | AE18: =AD18-AD$14 -> -20.991932 | AF18: =AD18-AD$17 -> 20.515039 | AG18: =AF18/AD17 -> 0.20255971
C19: FCET | D19: 126.16024 | E19: =D19-D$14 -> 64.994582 | F19: 129.06565 | G19: =F19-F$14 -> -8.684639 | H19: =F19-F$17 -> 26.674045 | J19: 126.16024 | K19: =J19-J$14 -> 64.994582 | L19: 117.03898 | M19: =L19-L$14 -> -20.711308 | N19: =L19-L$17 -> 14.647377 | P19: 126.16024 | Q19: =P19-P$14 -> 64.994582 | R19: 112.7451 | S19: =R19-R$14 -> -25.005192 | T19: =R19-R$17 -> 10.353493 | V19: 126.16024 | W19: =V19-V$14 -> 64.994582 | X19: 122.07805 | Y19: =X19-X$14 -> -15.672234 | Z19: =X19-X$17 -> 14.530231 | AB19: ='B3 - TCO ML 48T '!C170 -> 121.54817 | AC19: =AB19-AB$14 -> 60.382513 | AD19: ='B3 - TCO ML 48T '!AG170 -> 121.65824 | AE19: =AD19-AD$14 -> -21.127701 | AF19: =AD19-AD$17 -> 20.379269 | AG19: =AF19/AD17 -> 0.20121916
C20: Diesel - 10% | D20: 55.04909 | F20: 123.97526 | J20: 55.04909 | L20: 123.97526 | P20: 55.04909 | R20: 123.97526 | V20: 55.04909 | X20: 123.97526 | AB20: ='B3 - TCO ML 48T '!C171 -> 55.04909 | AD20: ='B3 - TCO ML 48T '!AG171 -> 128.50735
A22: B5 | B22: 28T Parcel Load (H2 Cost in 2055 - 220/70) | C22: Diesel | D22: 41.09072 | F22: 92.495171 | J22: 41.09072 | L22: 92.495171 | P22: 41.09072 | R22: 92.495171 | V22: 41.09072 | X22: 92.495171 | AB22: ='B5 - TCO PL&FMCG 28T '!C165 -> 41.09072 | AD22: ='B5 - TCO PL&FMCG 28T '!AG165 -> 95.740371
C23: CNG | D23: 39.969475 | E23: =D23-D$22 -> -1.1212456 | F23: 96.76515 | G23: =F23-F$22 -> 4.2699791 | J23: 39.969475 | K23: =J23-J$22 -> -1.1212456 | L23: 96.76515 | M23: =L23-L$22 -> 4.2699791 | P23: 39.969475 | Q23: =P23-P$22 -> -1.1212456 | R23: 96.76515 | S23: =R23-R$22 -> 4.2699791 | V23: 39.969475 | W23: =V23-V$22 -> -1.1212456 | X23: 96.76515 | Y23: =X23-X$22 -> 4.2699791 | AB23: ='B5 - TCO PL&FMCG 28T '!C166 -> 39.969475 | AC23: =AB23-AB$22 -> -1.1212456 | AD23: ='B5 - TCO PL&FMCG 28T '!AG166 -> 103.66877 | AE23: =AD23-AD$22 -> 7.9283973
C24: LNG | D24: 40.206321 | E24: =D24-D$22 -> -0.88439972 | F24: 96.507024 | G24: =F24-F$22 -> 4.0118524 | J24: 40.206321 | K24: =J24-J$22 -> -0.88439972 | L24: 96.507024 | M24: =L24-L$22 -> 4.0118524 | P24: 40.206321 | Q24: =P24-P$22 -> -0.88439972 | R24: 96.507024 | S24: =R24-R$22 -> 4.0118524 | V24: 40.206321 | W24: =V24-V$22 -> -0.88439972 | X24: 96.507024 | Y24: =X24-X$22 -> 4.0118524 | AB24: ='B5 - TCO PL&FMCG 28T '!C167 -> 40.206321 | AC24: =AB24-AB$22 -> -0.88439972 | AD24: ='B5 - TCO PL&FMCG 28T '!AG167 -> 102.65036 | AE24: =AD24-AD$22 -> 6.9099916
C25: BET | D25: 56.428695 | E25: =D25-D$22 -> 15.337974 | F25: 73.390132 | G25: =F25-F$22 -> -19.10504 | H25: =F25-F$25 -> 0 | J25: 56.428695 | K25: =J25-J$22 -> 15.337974 | L25: 73.390132 | M25: =L25-L$22 -> -19.10504 | N25: =L25-L$25 -> 0 | P25: 56.428695 | Q25: =P25-P$22 -> 15.337974 | R25: 73.390132 | S25: =R25-R$22 -> -19.10504 | T25: =R25-R$25 -> 0 | V25: 56.428695 | W25: =V25-V$22 -> 15.337974 | X25: 77.782466 | Y25: =X25-X$22 -> -14.712705 | Z25: =X25-X$25 -> 0 | AB25: ='B5 - TCO PL&FMCG 28T '!C168 -> 49.44802 | AC25: =AB25-AB$22 -> 8.3572991 | AD25: ='B5 - TCO PL&FMCG 28T '!AG168 -> 72.442334 | AE25: =AD25-AD$22 -> -23.298037
C26: H2-ICE | D26: 83.028023 | E26: =D26-D$22 -> 41.937302 | F26: 89.567502 | G26: =F26-F$22 -> -2.9276693 | H26: =F26-F$25 -> 16.17737 | J26: 83.028023 | K26: =J26-J$22 -> 41.937302 | L26: 79.233476 | M26: =L26-L$22 -> -13.261696 | N26: =L26-L$25 -> 5.8433441 | P26: 83.028023 | Q26: =P26-P$22 -> 41.937302 | R26: 75.543916 | S26: =R26-R$22 -> -16.951255 | T26: =R26-R$25 -> 2.1537844 | V26: 83.028023 | W26: =V26-V$22 -> 41.937302 | X26: 83.563346 | Y26: =X26-X$22 -> -8.9318253 | Z26: =X26-X$25 -> 5.7808799 | AB26: ='B5 - TCO PL&FMCG 28T '!C169 -> 79.06506 | AC26: =AB26-AB$22 -> 37.974339 | AD26: ='B5 - TCO PL&FMCG 28T '!AG169 -> 83.202618 | AE26: =AD26-AD$22 -> -12.537753 | AF26: =AD26-AD$25 -> 10.760284 | AG26: =AF26/AD25 -> 0.14853585
C27: FCET | D27: 85.736155 | E27: =D27-D$22 -> 44.645435 | F27: 88.08965 | G27: =F27-F$22 -> -4.4055214 | H27: =F27-F$25 -> 14.699518 | J27: 85.736155 | K27: =J27-J$22 -> 44.645435 | L27: 80.33913 | M27: =L27-L$22 -> -12.156041 | N27: =L27-L$25 -> 6.9489986 | P27: 85.736155 | Q27: =P27-P$22 -> 44.645435 | R27: 77.57196 | S27: =R27-R$22 -> -14.923211 | T27: =R27-R$25 -> 4.1818288 | V27: 85.736155 | W27: =V27-V$22 -> 44.645435 | X27: 83.586533 | Y27: =X27-X$22 -> -8.9086384 | Z27: =X27-X$25 -> 5.8040668 | AB27: ='B5 - TCO PL&FMCG 28T '!C170 -> 82.763933 | AC27: =AB27-AB$22 -> 41.673212 | AD27: ='B5 - TCO PL&FMCG 28T '!AG170 -> 83.315987 | AE27: =AD27-AD$22 -> -12.424384 | AF27: =AD27-AD$25 -> 10.873653 | AG27: =AF27/AD25 -> 0.15010081
C28: Diesel - 10% | D28: 36.981648 | F28: 83.245654 | J28: 36.981648 | L28: 83.245654 | P28: 36.981648 | R28: 83.245654 | V28: 36.981648 | X28: 83.245654 | AB28: ='B5 - TCO PL&FMCG 28T '!C171 -> 36.981648 | AD28: ='B5 - TCO PL&FMCG 28T '!AG171 -> 86.166334
A30: B6 | B30: 15T Perishables (H2 Cost in 2055 - 220/70) | C30: Diesel | D30: 29.688488 | F30: 66.564521 | J30: 29.688488 | L30: 66.564521 | P30: 29.688488 | R30: 66.564521 | V30: 29.688488 | X30: 66.564521 | AB30: ='B6 Perishables 15T'!C165 -> 29.688488 | AD30: ='B6 Perishables 15T'!AG165 -> 68.998421
C31: CNG | D31: 29.047288 | E31: =D31-D$30 -> -0.6411998 | F31: 70.25773 | G31: =F31-F$30 -> 3.6932086 | J31: 29.047288 | K31: =J31-J$30 -> -0.6411998 | L31: 70.25773 | M31: =L31-L$30 -> 3.6932086 | P31: 29.047288 | Q31: =P31-P$30 -> -0.6411998 | R31: 70.25773 | S31: =R31-R$30 -> 3.6932086 | V31: 29.047288 | W31: =V31-V$30 -> -0.6411998 | X31: 70.25773 | Y31: =X31-X$30 -> 3.6932086 | AB31: ='B6 Perishables 15T'!C166 -> 29.047288 | AC31: =AB31-AB$30 -> -0.6411998 | AD31: ='B6 Perishables 15T'!AG166 -> 75.517629 | AE31: =AD31-AD$30 -> 6.5192081
C32: LNG | D32: 29.334585 | E32: =D32-D$30 -> -0.35390248 | F32: 70.283392 | G32: =F32-F$30 -> 3.7188706 | J32: 29.334585 | K32: =J32-J$30 -> -0.35390248 | L32: 70.283392 | M32: =L32-L$30 -> 3.7188706 | P32: 29.334585 | Q32: =P32-P$30 -> -0.35390248 | R32: 70.283392 | S32: =R32-R$30 -> 3.7188706 | V32: 29.334585 | W32: =V32-V$30 -> -0.35390248 | X32: 70.283392 | Y32: =X32-X$30 -> 3.7188706 | AB32: ='B6 Perishables 15T'!C167 -> 29.334585 | AC32: =AB32-AB$30 -> -0.35390248 | AD32: ='B6 Perishables 15T'!AG167 -> 74.928355 | AE32: =AD32-AD$30 -> 5.9299344
C33: BET | D33: 41.115025 | E33: =D33-D$30 -> 11.426537 | F33: 52.614452 | G33: =F33-F$30 -> -13.950069 | H33: =F33-F$33 -> 0 | J33: 41.115025 | K33: =J33-J$30 -> 11.426537 | L33: 52.614452 | M33: =L33-L$30 -> -13.950069 | N33: =L33-L$33 -> 0 | P33: 41.115025 | Q33: =P33-P$30 -> 11.426537 | R33: 54.630322 | S33: =R33-R$30 -> -11.934199 | T33: =R33-R$33 -> 0 | V33: 41.115025 | W33: =V33-V$30 -> 11.426537 | X33: 55.86096 | Y33: =X33-X$30 -> -10.703561 | Z33: =X33-X$33 -> 0 | AB33: ='B6 Perishables 15T'!C169 -> 58.383175 | AC33: =AB33-AB$30 -> 28.694687 | AD33: ='B6 Perishables 15T'!AG168 -> 51.913906 | AE33: =AD33-AD31 -> -23.603723
C34: H2-ICE | D34: 61.355397 | E34: =D34-D$30 -> 31.666909 | F34: 65.148012 | G34: =F34-F$30 -> -1.4165094 | H34: =F34-F$33 -> 12.53356 | J34: 61.355397 | K34: =J34-J$30 -> 31.666909 | L34: 57.397492 | M34: =L34-L$30 -> -9.1670292 | N34: =L34-L$33 -> 4.7830402 | P34: 61.633175 | Q34: =P34-P$30 -> 31.944687 | R34: 52.614452 | S34: =R34-R$30 -> -13.950069 | T34: =R34-R$33 -> -2.0158704 | V34: 61.355397 | W34: =V34-V$30 -> 31.666909 | X34: 60.644895 | Y34: =X34-X$30 -> -5.9196265 | Z34: =X34-X$33 -> 4.7839348 | AB34: ='B6 Perishables 15T'!C168 -> 35.955395 | AC34: =AB34-AB$30 -> 6.2669075 | AD34: ='B6 Perishables 15T'!AG169 -> 60.374349 | AE34: =AD34-AD30 -> -8.6240719 | AF34: =AD34-AD$33 -> 8.460443 | AG34: =AF34/AD33 -> 0.16297065
C35: FCET | D35: 65.995979 | E35: =D35-D$30 -> 36.307492 | F35: 64.954579 | G35: =F35-F$30 -> -1.6099417 | H35: =F35-F$33 -> 12.340128 | J35: 65.995979 | K35: =J35-J$30 -> 36.307492 | L35: 59.141689 | M35: =L35-L$30 -> -7.4228315 | N35: =L35-L$33 -> 6.5272378 | P35: 65.995979 | Q35: =P35-P$30 -> 36.307492 | R35: 57.066312 | S35: =R35-R$30 -> -9.4982089 | T35: =R35-R$33 -> 2.4359901 | V35: 65.995979 | W35: =V35-V$30 -> 36.307492 | X35: 61.577241 | Y35: =X35-X$30 -> -4.9872795 | Z35: =X35-X$33 -> 5.7162818 | AB35: ='B6 Perishables 15T'!C170 -> 63.766813 | AC35: =AB35-AB$30 -> 34.078325 | AD35: ='B6 Perishables 15T'!AG170 -> 61.374332 | AE35: =AD35-AD$30 -> -7.6240884 | AF35: =AD35-AD$33 -> 9.4604264 | AG35: =AF35/AD33 -> 0.18223299
C36: Diesel - 10% | D36: 26.719639 | F36: 59.908069 | J36: 26.719639 | L36: 59.908069 | P36: 26.719639 | R36: 59.908069 | V36: 26.719639 | X36: 59.908069 | AB36: ='B6 Perishables 15T'!C171 -> 26.719639 | AD36: ='B6 Perishables 15T'!AG171 -> 62.098578
A38: B7 | B38: 28Tipper Const. & Mining (H2 Cost in 2055 - 220/70) | C38: Diesel | D38: 61.604723 | F38: 144.77967 | J38: 61.604723 | L38: 144.77967 | P38: 61.604723 | R38: 144.77967 | V38: 61.604723 | X38: 144.77967 | AB38: ='B7 C&M 28Tip'!C165 -> 61.604723 | AD38: ='B7 C&M 28Tip'!AG165 -> 148.62267
C39: CNG | D39: 60.93252 | E39: =D39-D$38 -> -0.67220325 | F39: 154.16757 | G39: =F39-F$38 -> 9.387899 | J39: 60.93252 | K39: =J39-J$38 -> -0.67220325 | L39: 154.16757 | M39: =L39-L$38 -> 9.387899 | P39: 60.93252 | Q39: =P39-P$38 -> -0.67220325 | R39: 154.16757 | S39: =R39-R$38 -> 9.387899 | V39: 60.93252 | W39: =V39-V$38 -> -0.67220325 | X39: 154.16757 | Y39: =X39-X$38 -> 9.387899 | AB39: ='B7 C&M 28Tip'!C166 -> 60.93252 | AC39: =AB39-AB$38 -> -0.67220325 | AD39: ='B7 C&M 28Tip'!AG166 -> 162.45191 | AE39: =AD39-AD$38 -> 13.829241
C40: LNG | D40: 61.463428 | E40: =D40-D$38 -> -0.14129574 | F40: 150.80704 | G40: =F40-F$38 -> 6.0273686 | J40: 61.463428 | K40: =J40-J$38 -> -0.14129574 | L40: 150.80704 | M40: =L40-L$38 -> 6.0273686 | P40: 61.463428 | Q40: =P40-P$38 -> -0.14129574 | R40: 150.80704 | S40: =R40-R$38 -> 6.0273686 | V40: 61.463428 | W40: =V40-V$38 -> -0.14129574 | X40: 150.80704 | Y40: =X40-X$38 -> 6.0273686 | AB40: ='B7 C&M 28Tip'!C167 -> 61.463428 | AC40: =AB40-AB$38 -> -0.14129574 | AD40: ='B7 C&M 28Tip'!AG167 -> 158.13179 | AE40: =AD40-AD$38 -> 9.5091192
C41: BET | D41: 83.905941 | E41: =D41-D$38 -> 22.301218 | F41: 119.36107 | G41: =F41-F$38 -> -25.418602 | H41: =F41-F$41 -> 0 | J41: 83.905941 | K41: =J41-J$38 -> 22.301218 | L41: 119.36107 | M41: =L41-L$38 -> -25.418602 | N41: =L41-L$41 -> 0 | P41: 83.905941 | Q41: =P41-P$38 -> 22.301218 | R41: 119.36107 | S41: =R41-R$38 -> -25.418602 | T41: =R41-R$41 -> 0 | V41: 83.905941 | W41: =V41-V$38 -> 22.301218 | X41: 123.77636 | Y41: =X41-X$38 -> -21.003309 | Z41: =X41-X$41 -> 0 | AB41: ='B7 C&M 28Tip'!C168 -> 76.014743 | AC41: =AB41-AB$38 -> 14.41002 | AD41: ='B7 C&M 28Tip'!AG168 -> 118.28965 | AE41: =AD41-AD$38 -> -30.333024
C42: H2-ICE | D42: 112.41617 | E42: =D42-D$38 -> 50.811448 | F42: 141.56311 | G42: =F42-F$38 -> -3.2165622 | H42: =F42-F$41 -> 22.20204 | J42: 112.41617 | K42: =J42-J$38 -> 50.811448 | L42: 129.32545 | M42: =L42-L$38 -> -15.454225 | N42: =L42-L$41 -> 9.9643767 | P42: 112.41617 | Q42: =P42-P$38 -> 50.811448 | R42: 124.95623 | S42: =R42-R$38 -> -19.82344 | T42: =R42-R$41 -> 5.5951613 | V42: 112.41617 | W42: =V42-V$38 -> 50.811448 | X42: 134.45292 | Y42: =X42-X$38 -> -10.326747 | Z42: =X42-X$41 -> 10.676562 | AB42: ='B7 C&M 28Tip'!C169 -> 107.72319 | AC42: =AB42-AB$38 -> 46.118466 | AD42: ='B7 C&M 28Tip'!AG169 -> 134.02575 | AE42: =AD42-AD$38 -> -14.596924 | AF42: =AD42-AD$41 -> 15.7361 | AG42: =AF42/AD41 -> 0.13303024
C43: FCET | D43: 122.80206 | E43: =D43-D$38 -> 61.197332 | F43: 138.98049 | G43: =F43-F$38 -> -5.7991809 | H43: =F43-F$41 -> 19.619421 | J43: 122.80206 | K43: =J43-J$38 -> 61.197332 | L43: 129.80224 | M43: =L43-L$38 -> -14.977428 | N43: =L43-L$41 -> 10.441174 | P43: 122.80206 | Q43: =P43-P$38 -> 61.197332 | R43: 126.52533 | S43: =R43-R$38 -> -18.25434 | T43: =R43-R$41 -> 7.1642621 | V43: 122.80206 | W43: =V43-V$38 -> 61.197332 | X43: 133.64785 | Y43: =X43-X$38 -> -11.131819 | Z43: =X43-X$41 -> 9.8714894 | AB43: ='B7 C&M 28Tip'!C170 -> 119.28232 | AC43: =AB43-AB$38 -> 57.677595 | AD43: ='B7 C&M 28Tip'!AG170 -> 133.32747 | AE43: =AD43-AD$38 -> -15.295202 | AF43: =AD43-AD$41 -> 15.037822 | AG43: =AF43/AD41 -> 0.12712712
C44: Diesel - 10% | D44: 55.444251 | F44: 130.3017 | J44: 55.444251 | L44: 130.3017 | P44: 55.444251 | R44: 130.3017 | V44: 55.444251 | X44: 130.3017 | AB44: ='B7 C&M 28Tip'!C171 -> 55.444251 | AD44: ='B7 C&M 28Tip'!AG171 -> 133.7604
A46: B10 | B46: 55T TT Cement (H2 Cost in 2055 - 220/70) | C46: Diesel | D46: 64.079057 | F46: 141.8243 | J46: 64.079057 | L46: 141.8243 | P46: 64.079057 | R46: 141.8243 | V46: 64.079057 | X46: 141.8243 | AB46: ='B10 Cement 55 Tractor '!C165 -> 64.079057 | AD46: ='B10 Cement 55 Tractor '!AG165 -> 147.44099
...

Sheet Results
C3: Parameter Values | D3: PT Mix - 2045 Estimates | J3: PT Mix - 2055 Estimates | N3: CO2 Reduction (Cum.) | O3: Cum. Diesel Savings | P3: H2 Reqd. in 2055 | Q3: Energy Reqd. in 2055
D4: Diesel | E4: CNG | F4: LNG | G4: BET | H4: H2 ICE | I4: H2 FCET | J4: BET | K4: H2 ICE | L4: H2 FCET | N4: Bil. Tons | O4: Bil. Ltrs. | P4: Mil. Tons | Q4: TWh
D5: ='Estimation SS2045'!R174 -> 0.096140252 | E5: ='Estimation SS2045'!S174 -> 0.049059805 | F5: ='Estimation SS2045'!T174 -> 0.0048070126 | G5: ='Estimation SS2045'!U174 -> 0.76063905 | H5: ='Estimation SS2045'!V174 -> 0.04934257 | I5: ='Estimation SS2045'!W174 -> 0.040152693 | J5: ='Estimation 100% ZET 2055'!O161 -> 0.87248713 | K5: ='Estimation 100% ZET 2055'!P161 -> 0.065941536 | L5: ='Estimation 100% ZET 2055'!Q161 -> 0.061571331 | N5: ='Emissions '!K118 -> 4622.0332 | O5: ='Energy Requirementsfinal'!E198 -> 2570.3878 | P5: ='Energy Requirementsfinal'!M197 -> 13.205755 | Q5: ='Energy Requirementsfinal'!J197 -> 903.35203
D6: ='Estimation SS2045'!R175 -> 68000 | E6: ='Estimation SS2045'!S175 -> 34700 | F6: ='Estimation SS2045'!T175 -> 3400 | G6: ='Estimation SS2045'!U175 -> 538000 | H6: ='Estimation SS2045'!V175 -> 34900 | I6: ='Estimation SS2045'!W175 -> 28400 | J6: ='Estimation 100% ZET 2055'!O162 -> 898400 | K6: ='Estimation 100% ZET 2055'!P162 -> 67900 | L6: ='Estimation 100% ZET 2055'!Q162 -> 63400

Sheet Dashboard
B3: Parameters | C3: What | E3: How | F3: Values/ Restriction | G3: Default
A4: 1 | B4: Diesel/LNG/CNG Price | C4: Value | D4: Year | E4: Drop down | F4: 2026 to 2055
D5: Value | E5: Value Entry | F5: Max. Rs.500
C6: CAGR % | D6: Year range | E6: Drop down | F6: 2025-30 2031-35 2036-40 2041-45 2046-50 2051-55
D7: Change % | E7: Value Entry | F7: Max. 10%
A8: 2 | B8: Energy Price (incl. CAAS) | C8: Value | D8: Year | E8: Drop down | F8: 2026 to 2055
D9: Value | E9: Value Entry | F9: Max. Rs.500
C10: CAGR % | D10: Year range | E10: Drop down | F10: 2025-30 2031-35 2036-40 2041-45 2046-50 2051-55
D11: Change % | E11: Value Entry | F11: Max. 10%
A12: 3 | B12: Green H2 Prodn. Cost | C12: Value | D12: Year | E12: Drop down | F12: 2026 to 2055
D13: Value | E13: Value Entry | F13: Max. Rs.500
C14: CAGR % | D14: Year range | E14: Drop down | F14: 2025-30 2031-35 2036-40 2041-45 2046-50 2051-55
D15: Change % | E15: Value Entry | F15: Max. 10%
A16: 4 | B16: H2 Compression, Transportation & Dispense Cost | C16: Value | D16: Year | E16: Drop down | F16: 2026 to 2055
D17: Value | E17: Value Entry | F17: Max. Rs.500
C18: CAGR % | D18: Year range | E18: Drop down | F18: 2025-30 2031-35 2036-40 2041-45 2046-50 2051-55
D19: Change % | E19: Value Entry | F19: Max. 10%
A20: 5 | B20: Battery Price / kWh | C20: Value | D20: Year | E20: Drop down | F20: 2026 to 2055
D21: Value | E21: Value Entry | F21: Max. Rs.500
C22: CAGR % | D22: Year range | E22: Drop down | F22: 2025-30 2031-35 2036-40 2041-45 2046-50 2051-55
D23: Change % | E23: Value Entry | F23: Max. 10%
A24: 6 | B24: Fuel Cell Price / kW | C24: Value | D24: Year | E24: Drop down | F24: 2026 to 2055
D25: Value | E25: Value Entry | F25: Max. Rs.500
C26: CAGR % | D26: Year range | E26: Drop down | F26: 2025-30 2031-35 2036-40 2041-45 2046-50 2051-55
D27: Change % | E27: Value Entry | F27: Max. 10%
A28: 7 | B28: Diesel Maintenance Cost/km (for Each Bucket) | D28: Bucket | E28: Drop down | F28: B1 to B14
C29: Maint. Cost | D29: Year | E29: Drop down | F29: 2026 to 2055
D30: Value | E30: Value Entry
C31: CAGR % | D31: Year range | E31: Drop down | F31: 2025-30 2031-35 2036-40 2041-45 2046-50 2051-55
D32: Change % | E32: Value Entry | F32: Max. 10%
A33: 8 | B33: BET Related Aggregates Maintenance Cost/km incl Battery Replacement (for Each Bucket) | D33: Bucket | E33: Drop down | F33: B1 to B14
C34: Maint. Cost | D34: Year | E34: Drop down | F34: 2026 to 2055
D35: Value | E35: Value Entry
C36: CAGR % | D36: Year range | E36: Drop down | F36: 2025-30 2031-35 2036-40 2041-45 2046-50 2051-55
D37: Change % | E37: Value Entry | F37: Max. 10%
A38: 9 | B38: FCET Related Aggregates Maintenance Cost/km incl Battery & FC Replacement (for Each Bucket) | D38: Bucket | E38: Drop down | F38: B1 to B14
C39: Maint. Cost | D39: Year | E39: Drop down | F39: 2026 to 2055
D40: Value | E40: Value Entry
C41: CAGR % | D41: Year range | E41: Drop down | F41: 2025-30 2031-35 2036-40 2041-45 2046-50 2051-55
D42: Change % | E42: Value Entry | F42: Max. 10%
...

Sheet Input Parameters
A1: Parameter Assumptions:
A2: Sl. No. | B2: Parameter | E2: Assumptions/Values & Trend | H2: Remarks
E3: Base Value (2025) | F3: Trend | G3: Value (2055)
A4: 1 | B4: Product Pilot Year/ Base Year | C4: Diesel/CNG/LNG | D4: Year | E4: 2025 | H4: Based on discussions with OEMs, Fuel & Energy producers/Suppliers, Charging Service Providers, Tier 1 Suppliers, Industry Experts & other relevant stakeholders
C5: BET | E5: 2025
C6: H2 ICE | E6: 2028
C7: H2 FCET | E7: 2030
A8: 2 | B8: Product Start of Sale - All Geography/Variants Year | C8: CNG | E8: 2028
C9: LNG | E9: 2028
C10: BET | E10: 2027
C11: H2 ICE | E11: 2034
C12: H2 FCET | E12: 2038
A13: 3 | B13: Power Train Maturity Year - Products, Technology & Eco-system | C13: CNG | E13: 2030
C14: LNG | E14: 2033
C15: BET | E15: 2035
C16: H2 ICE | E16: 2042
C17: H2 FCET | E17: 2045
A18: 4 | B18: Inflection Point (3% Share) | C18: BET | E18: 2032
C19: H2 ICE | E19: 2049
C20: H2 FCET | E20: 2050
A21: 5 | B21: ICE Trucks Price (Diesel/CNG/LNG/H2) - On-road Price for Fully Built Trucks including taxes & registration | C21: Diesel Truck Price | D21: INR | E21: On-road price of each model | F21: 3.0% Annual Increase (based on past trend) | H21: Rs. 4,00,000/- increase for BS7 effective 2030
C22: CNG Cylinder System Capacity | D22: Litres/Kg. | E22: 480 l/96 kg 15T Trucks & 960 l/192 kg. for Heavier trucks | H22: CNG Option for Rigid Trucks only
C23: CNG Cylinder Cost | D23: INR | E23: Rs.1,50,000/- & Rs.2,50,000/- | F23: 3.0% Annual Increase
C24: CNG Truck Price | D24: INR | E24: Diesel Truck Price + CNG Cylinder System Cost
C25: LNG Cylinder System Capacity | D25: Litres/Kg. | E25: 450 l/158 kg for 40T Trucks & 990 l/ 347 kg. for Heavier Trucks | H25: - LNG Option for Articulated Trucks only - Lower CAGR for LNG Cylinders due to cost reduction on account of indiginization & volume build up
C26: LNG Cylinder Cost per kg. of LNG | D26: INR | E26: Rs.3050/- | F26: 1.0% Annual Increase | G26: Rs.4100/-
C27: LNG Pipe/Valves System Cost | D27: INR | E27: Rs.1,00,000/- per Truck | F27: 1.0% Annual Increase | G27: Rs.1,35,000/-
C28: LNG Truck Price | D28: INR | E28: Diesel Truck Price + LNG Cyl Cost + LNG Valves System Cost
C29: H2 Cylinder System Capacity | D29: Litres/Kg. | E29: 1200 litres/28 kg
C30: H2 Cylinder Cost per kg. of H2 | D30: INR | E30: Rs.56,000/- | F30: 2026-30: -5.0% 2031-40: -4.0% 2041-50: +1.0% 2051-55: +1.0% | G30: Rs.33,500/- | H30: Reduction in cost initially through Indiginesation & Increased Capacity Utilization
C31: H2 Truck Price | D31: INR | E31: Diesel Truck Price + H2 Cylinder System Cost
A32: 6 | B32: BET Price | C32: Diesel Engine & Transmission Cost | D32: INR | E32: 3 sets of values for various GVW of trucks | F32: 2.0% Annual Increase
C33: ePowertrain Cost | D33: INR | E33: Rs.14,00,000/- for 4x2 Trucks & Rs.17,00,000/- for Heavier Trucks | F33: 2026-30: -4.0% 2031-40: -1.0% 2041-50: +1.0% 2051-55: +1.0% | G33: Rs.12,00,000/- & Rs.14,55,000/- | H33: Reduction in cost initially through Technology Improvements, Indiginesation & Increased Capacity Utilization
C34: Battery Pack Capacity, kWh | D34: kWh | E34: 200-350 kWh for various Models
C35: Battery Pack Cost per kWh | D35: INR | E35: Rs.9,900/- (USD110) | F35: 2026-30: -1.5% 2031-40: -2.5.% 2041-50: -1.0% 2051-55: +1.0% | G35: Rs.6,800/- | H35: Reduction in cost initially through Technology Improvements, Indiginesation & Increased Capacity Utilization
C36: BET Mfg. & Other Costs (% of Battery & ePowertrain Costs | D36: % | E36: 2026-30: from 50% to 35% progressively 2031-40: 30% 2041-55: 25 % | H36: - Additional Cost for Investment on Manufacturing Facilities & Margin. - Reduction over a period as capacity builds up
C37: BET Price | D37: INR | E37: Diesel Truck Price - (Engine & Transmission Costs) + ePowertrain Cost + Battery Cost + BET Mfg. Costs
A38: 7 | B38: FCET Price | C38: Fuel Cell Cost per kW | D38: INR | E38: Rs.36,000/- | F38: 2026-30: -3.0% 2031-40: -3.0.% 2041-50: -2.0% 2051-55: +1.0% | G38: Rs.19,600/- | H38: Reduction in cost initially through Technology Improvements, Indiginesation & Increased Capacity Utilization
C39: Fuel Cell Power Rating | D39: kW | E39: 80 kW for upto 40T Trucks & 120 kW for Heavier Trucks
C40: Battery Pack Capacity for FCET | D40: kWh | E40: 70 kWh for upto 40T Trucks & 80 kWh for Heavier Trucks
...

Sheet Charge station economics
A1: Economics of BET charging infrastructure - 4 nos. 240kW chargers
A3: Space required for 1 BET charging bay | B3: =75*25 -> 1875
A4: Space required for waiting vehicle | B4: =75*25 -> 1875
A5: Space required for maneuvring | B5: 1250
A6: Space required per charging bay | B6: =SUM(B3:B5) -> 5000
A7: Area per acre in sft | B7: 43636
A8: Less - Allowance for land constraints / office space | B8: -3636
A9: Available for charger bay | B9: =B8+B7 -> 40000
A10: No. of bays possible in 1 acre * | B10: =B9/B6 -> 8
A11: * Can be slightly higher in captive chargers (eg. In warehouses, factories where waiting space need not be high)
A13: Assuming land cost of Rs.2 crores per acre :
A15: For 0.5 acre plot / 2 chargers
B16: Rs. Lacs
A17: Land cost | B17: 100
A18: Cost of 240kW chargers (20L x4) | B18: 80 | C18: (includes civil work, installation)
A19: Power connection expenses (HT line, transformer etc) | B19: 20
A20: Capex excluding land | B20: =B18+B19 -> 100
A21: Assuming 25 days/month operation; for 4 chargers - energy dispensation
A23: For Captive user (Shipper / Operator) | B23: 2026 | C23: 2027 | D23: 2028 | E23: 2029 | F23: 2030 | G23: 2031 | H23: 2032 | I23: 2033 | J23: 2034 | K23: 2035 | L23: 2036 | M23: 2037 | N23: 2038 | O23: 2039 | P23: 2040 | Q23: 2041 | R23: 2042 | S23: 2043 | T23: 2044 | U23: 2045 | V23: 2046 | W23: 2047 | X23: 2048 | Y23: 2049 | Z23: 2050 | AA23: 2051 | AB23: 2052 | AC23: 2053 | AD23: 2054 | AE23: 2055
A24: Monthly demand charges (for 960kW) - Rs. 305/kVA; power factor taken as 0.98 (Rs. Lacs) | B24: =305*960/0.98/100000 -> 2.9877551 | C24: =B24 -> 2.9877551 | D24: =C24 -> 2.9877551 | E24: =D24 -> 2.9877551 | F24: =E24 -> 2.9877551 | G24: =F24 -> 2.9877551 | H24: =G24 -> 2.9877551 | I24: =H24 -> 2.9877551 | J24: =I24 -> 2.9877551 | ... AE24: =AD24 -> 2.9877551
A25: Man power (2 person / 2 shift) - Rs. Lacs | B25: 1 | C25: =B25*1.07 -> 1.07 | D25: =C25*1.07 -> 1.1449 | E25: =D25*1.07 -> 1.225043 | F25: =E25*1.07 -> 1.310796 | G25: =F25*1.07 -> 1.4025517 | H25: =G25*1.07 -> 1.5007304 | I25: =H25*1.07 -> 1.6057815 | J25: =I25*1.07 -> 1.7181862 | ... AE25: =AD25*1.07 -> 7.114257
A26: Administrative overheads @10% of manpower cost Rs. Lacs | B26: =B25*0.1 -> 0.1 | C26: =C25*0.1 -> 0.107 | D26: =D25*0.1 -> 0.11449 | E26: =E25*0.1 -> 0.1225043 | F26: =F25*0.1 -> 0.1310796 | G26: =G25*0.1 -> 0.14025517 | H26: =H25*0.1 -> 0.15007304 | I26: =I25*0.1 -> 0.16057815 | ... AE26: =AE25*0.1 -> 0.7114257
A27: Fixed cost per month (Rs. Lacs) | B27: =SUM(B24:B26) -> 4.0877551 | C27: =SUM(C24:C26) -> 4.1647551 | D27: =SUM(D24:D26) -> 4.2471451 | E27: =SUM(E24:E26) -> 4.3353024 | F27: =SUM(F24:F26) -> 4.4296307 | G27: =SUM(G24:G26) -> 4.530562 | H27: =SUM(H24:H26) -> 4.6385585 | I27: =SUM(I24:I26) -> 4.7541147 | ... AE27: =SUM(AE24:AE26) -> 10.813438
A28: No. of hours operated per day | B28: 8 | C28: 9 | D28: 10 | E28: 12 | F28: 14 | G28: 14 | H28: 14 | I28: 14 | J28: 14 | K28: 14 | L28: 14 | M28: 14 | N28: 14 | O28: 14 | P28: 14 | Q28: 14 | R28: 14 | S28: 14 | T28: 14 | U28: 14 | V28: 14 | W28: 14 | X28: 14 | Y28: 14 | Z28: 14 | AA28: 14 | AB28: 14 | AC28: 14 | AD28: 14 | AE28: 14
A29: Capacity utilisation (based on max 20 hrs charging / day) | B29: =B28/20 -> 0.4 | C29: =C28/20 -> 0.45 | D29: =D28/20 -> 0.5 | E29: =E28/20 -> 0.6 | F29: =F28/20 -> 0.7 | G29: =G28/20 -> 0.7 | H29: =H28/20 -> 0.7 | I29: =I28/20 -> 0.7 | ... AE29: =AE28/20 -> 0.7
A30: Energy dispensed per month (kWh) | B30: =B28*25*240*4 -> 192000 | C30: =C28*25*240*4 -> 216000 | D30: =D28*25*240*4 -> 240000 | E30: =E28*25*240*4 -> 288000 | F30: =F28*25*240*4 -> 336000 | G30: =G28*25*240*4 -> 336000 | H30: =H28*25*240*4 -> 336000 | I30: =I28*25*240*4 -> 336000 | ... AE30: =AE28*25*240*4 -> 336000
A31: Monthly fixed cost amortised over energy dispensed (Rs./kWh) | B31: =B27*100000/B30 -> 2.1290391 | C31: =C27*100000/C30 -> 1.9281274 | D31: =D27*100000/D30 -> 1.7696438 | E31: =E27*100000/E30 -> 1.5053133 | F31: =F27*100000/F30 -> 1.3183425 | G31: =G27*100000/G30 -> 1.3483815 | H31: =H27*100000/H30 -> 1.3805234 | I31: =I27*100000/I30 -> 1.4149151 | ... AE31: =AE27*100000/AE30 -> 3.2182851
A32: Total energy dispensed in 5 years (kWh) | B32: =12*SUM(B30:F30) -> 15264000
A33: Capex amortisation over 5 years (Rs./kWh) | B33: =B20*100000/B32 -> 0.65513627
A34: Total additional cost incurred by operator/shipper - Rs/kWh | B34: =B31+$B33 -> 2.7841754 | C34: =C31+$B33 -> 2.5832636 | D34: =D31+$B33 -> 2.4247801 | E34: =E31+$B33 -> 2.1604496 | F34: =F31+$B33 -> 1.9734787 | G34: =G31 -> 1.3483815 | H34: =H31 -> 1.3805234 | I34: =I31 -> 1.4149151 | J34: =J31 -> 1.4517143 | K34: =K31 -> 1.4910894 | L34: =L31 -> 1.5332207 | M34: =M31 -> 1.5783013 | N34: =N31 -> 1.6265375 | ... AE34: =AE31 -> 3.2182851
A36: For Charging As Service (CAS) operator | B36: 2026 | C36: 2027 | D36: 2028 | E36: 2029 | F36: 2030 | G36: 2031 | H36: 2032 | I36: 2033 | J36: 2034 | K36: 2035 | L36: 2036 | M36: 2037 | N36: 2038 | O36: 2039 | P36: 2040 | Q36: 2041 | R36: 2042 | S36: 2043 | T36: 2044 | U36: 2045 | V36: 2046 | W36: 2047 | X36: 2048 | Y36: 2049 | Z36: 2050 | AA36: 2051 | AB36: 2052 | AC36: 2053 | AD36: 2054 | AE36: 2055
A37: Monthly demand charges (for 960kW) - Rs. 305/kVA; power factor taken as 0.98 - Rs. Lacs | B37: =305*960/0.98/100000 -> 2.9877551 | C37: =B37 -> 2.9877551 | D37: =C37 -> 2.9877551 | E37: =D37 -> 2.9877551 | F37: =E37 -> 2.9877551 | G37: =F37 -> 2.9877551 | H37: =G37 -> 2.9877551 | I37: =H37 -> 2.9877551 | J37: =I37 -> 2.9877551 | ... AE37: =AD37 -> 2.9877551
A38: Man power cost (2 person / 2 shift) - Rs. Lacs | B38: 1 | C38: =B38*1.07 -> 1.07 | D38: =C38*1.07 -> 1.1449 | E38: =D38*1.07 -> 1.225043 | F38: =E38*1.07 -> 1.310796 | G38: =F38*1.07 -> 1.4025517 | H38: =G38*1.07 -> 1.5007304 | I38: =H38*1.07 -> 1.6057815 | J38: =I38*1.07 -> 1.7181862 | ... AE38: =AD38*1.07 -> 7.114257
A39: Land rental taken @ 4% pa & 3% increase pa - Rs. Lacs | B39: =B17*0.04/12 -> 0.33333333 | C39: =B39*1.03 -> 0.34333333 | D39: =C39*1.03 -> 0.35363333 | E39: =D39*1.03 -> 0.36424233 | F39: =E39*1.03 -> 0.3751696 | G39: =F39*1.03 -> 0.38642469 | H39: =G39*1.03 -> 0.39801743 | I39: =H39*1.03 -> 0.40995796 | J39: =I39*1.03 -> 0.42225669 | ... AE39: =AD39*1.03 -> 0.78552184
A40: Administrative overheads @5% of manpower cost Rs. Lacs | B40: =B38*0.05 -> 0.05 | C40: =C38*0.05 -> 0.0535 | D40: =D38*0.05 -> 0.057245 | E40: =E38*0.05 -> 0.06125215 | F40: =F38*0.05 -> 0.065539801 | G40: =G38*0.05 -> 0.070127587 | H40: =H38*0.05 -> 0.075036518 | I40: =I38*0.05 -> 0.080289074 | ... AE40: =AE38*0.05 -> 0.35571285
A41: Fixed cost per month | B41: =SUM(B37:B40) -> 4.3710884 | C41: =SUM(C37:C40) -> 4.4545884 | D41: =SUM(D37:D40) -> 4.5435334 | E41: =SUM(E37:E40) -> 4.6382926 | F41: =SUM(F37:F40) -> 4.7392605 | G41: =SUM(G37:G40) -> 4.8468591 | H41: =SUM(H37:H40) -> 4.9615394 | I41: =SUM(I37:I40) -> 5.0837836 | ... AE41: =SUM(AE37:AE40) -> 11.243247
A42: Capacity utilisation (based on max 20 hrs charging / day) | B42: 0.1 | C42: 0.15 | D42: 0.2 | E42: 0.25 | F42: 0.3 | G42: 0.35 | H42: 0.4 | I42: 0.5 | J42: 0.6 | K42: 0.7 | L42: 0.7 | M42: 0.7 | N42: 0.7 | O42: 0.7 | P42: 0.7 | Q42: 0.7 | R42: 0.7 | S42: 0.7 | T42: 0.7 | U42: 0.7 | V42: 0.7 | W42: 0.7 | X42: 0.7 | Y42: 0.7 | Z42: 0.7 | AA42: 0.7 | AB42: 0.7 | AC42: 0.7 | AD42: 0.7 | AE42: 0.7
A43: No. of hours operated per day | B43: =B42*20 -> 2 | C43: =C42*20 -> 3 | D43: =D42*20 -> 4 | E43: =E42*20 -> 5 | F43: =F42*20 -> 6 | G43: =G42*20 -> 7 | H43: =H42*20 -> 8 | I43: =I42*20 -> 10 | ... AE43: =AE42*20 -> 14
A44: Power dispensed per month (kW) | B44: =B43*25*240*4 -> 48000 | C44: =C43*25*240*4 -> 72000 | D44: =D43*25*240*4 -> 96000 | E44: =E43*25*240*4 -> 120000 | F44: =F43*25*240*4 -> 144000 | G44: =G43*25*240*4 -> 168000 | H44: =H43*25*240*4 -> 192000 | I44: =I43*25*240*4 -> 240000 | ... AE44: =AE43*25*240*4 -> 336000
A45: Monthly fixed cost amortised over power dispensed (Rs./kW) | B45: =B41*100000/B44 -> 9.1064342 | C45: =C41*100000/C44 -> 6.1869284 | D45: =D41*100000/D44 -> 4.7328473 | E45: =E41*100000/E44 -> 3.8652438 | F45: =F41*100000/F44 -> 3.2911531 | G45: =G41*100000/G44 -> 2.8850352 | H45: =H41*100000/H44 -> 2.5841351 | I45: =I41*100000/I44 -> 2.1182432 | ... AE45: =AE41*100000/AE44 -> 3.3462044
...

Sheet Charging trend
AF2: Remarks
